<?xml version="1.0"?>
<robot xmlns:xacro="http://www.ros.org/wiki/xacro">

  <!-- left_wheel-->
  <link
    name="left_wheel_link">
    <inertial>
    <mass value="0.5"/>
      <origin
        xyz="0.00566273525640093 -0.00989412534430653 -1.89986618215343E-07"
        rpy="0 0 0" />
    <inertia
        ixx="0.000209361851648379"
        ixy="1.5320155892368E-05"
        ixz="-1.41603895661375E-10"
        iyy="0.000207403161472826"
        iyz="2.96359099477467E-11"
        izz="0.000343890788216305" />
    </inertial>
    <visual>
      <origin
        xyz="0 0 0"
        rpy="0 0 0" />
      <geometry>
        <cylinder radius="0.05" length="0.075"/>
      </geometry>
      <material
        name="">
        <color
          rgba="0.79216 0.81961 0.93333 1" />
      </material>
    </visual>
    <collision>
      <origin
        xyz="0 0 0"
        rpy="0 0 0" />
      <geometry>
        <cylinder radius="0.05" length="0.075"/>
      </geometry>
    </collision>
  </link>

  <joint
    name="left_wheel_joint"
    type="continuous">
    <origin
      xyz="0 0.25 -0.025"
      rpy="-1.5708 0 0" />
    <parent
      link="base_link"/>
    <child
      link="left_wheel_link" />
    <axis
      xyz="0 0 1" />  <!--The diff drive plugin needs the axis pointing inwards. -->
  </joint>

  <gazebo reference="left_wheel_link">
    <visual>
      <material> <!-- Red -->
        <ambient>0.1 0.0 0.0 1.0</ambient>
        <diffuse>1.0 0.0 0.0 1.0</diffuse>
        <specular>0.5 0.0 0.0 1.0</specular>
        <emissive>0.0 0.0 0.0 1.0</emissive>
    </material>    
    </visual>
    <collision>
      <origin
        xyz="0 0 0"
        rpy="0 0 0" />
      <geometry>
        <cylinder radius="0.05" length="0.075"/>
      </geometry>
      <surface>
        <friction>
          <ode>
            <mu>1.0</mu> <!-- value range 0.0 to 1.0 -->
            <mu2>0.8</mu2> <!-- value range 0.0 to 1.0 -->
          </ode>
        </friction>
      </surface>
    </collision>
  </gazebo>

  <!-- right_wheel-->
  <link
    name="right_wheel_link">
    <inertial>
    <mass value="0.5"/>
      <origin
        xyz="0.00566273525640093 -0.00989412534430653 -1.89986618215343E-07"
        rpy="0 0 0" />
      <inertia
        ixx="0.000209361851648379"
        ixy="1.5320155892368E-05"
        ixz="-1.41603895661375E-10"
        iyy="0.000207403161472826"
        iyz="2.96359099477467E-11"
        izz="0.000343890788216305" />
    </inertial>
    <visual>
      <origin
        xyz="0 0 0"
        rpy="0 0 0" />
      <geometry>
        <cylinder radius="0.05" length="0.075"/>
      </geometry>
      <material
        name="">
        <color
          rgba="0.79216 0.81961 0.93333 1" />
      </material>
    </visual>
    <collision>
      <origin
        xyz="0 0 0"
        rpy="0 0 0" />
      <geometry>
        <cylinder radius="0.05" length="0.075"/>
      </geometry>
    </collision>
  </link>

  <joint
    name="right_wheel_joint"
    type="continuous">
    <origin
      xyz="0 -0.25 -0.025"
      rpy="1.5708 0 0" />
    <parent
      link="base_link"/>
    <child
      link="right_wheel_link" />
    <axis
      xyz="0 0 -1" />  <!--The diff drive plugin needs the axis pointing inwards. -->
  </joint>

  <gazebo reference="right_wheel_link">
    <visual>
      <material> <!-- Red -->
        <ambient>0.1 0.0 0.0 1.0</ambient>
        <diffuse>1.0 0.0 0.0 1.0</diffuse>
        <specular>0.5 0.0 0.0 1.0</specular>
        <emissive>0.0 0.0 0.0 1.0</emissive>
    </material>    
    </visual>
    <collision>
      <origin
        xyz="0 0 0"
        rpy="0 0 0" />
      <geometry>
        <cylinder radius="0.05" length="0.075"/>
      </geometry>
      <surface>
        <friction>
          <ode>
            <mu>1.0</mu> <!-- value range 0.0 to 1.0 -->
            <mu2>0.8</mu2> <!-- value range 0.0 to 1.0 -->
          </ode>
        </friction>
      </surface>
    </collision>
  </gazebo>

</robot>